[2023-04-27 08:18:56,066] {taskinstance.py:1159} INFO - Dependencies all met for <TaskInstance: attack_dag2.attack scheduled__2023-04-23T00:00:00+00:00 [queued]>
[2023-04-27 08:18:56,086] {taskinstance.py:1159} INFO - Dependencies all met for <TaskInstance: attack_dag2.attack scheduled__2023-04-23T00:00:00+00:00 [queued]>
[2023-04-27 08:18:56,087] {taskinstance.py:1356} INFO - 
--------------------------------------------------------------------------------
[2023-04-27 08:18:56,088] {taskinstance.py:1357} INFO - Starting attempt 1 of 1
[2023-04-27 08:18:56,089] {taskinstance.py:1358} INFO - 
--------------------------------------------------------------------------------
[2023-04-27 08:18:56,157] {taskinstance.py:1377} INFO - Executing <Task(PythonOperator): attack> on 2023-04-23 00:00:00+00:00
[2023-04-27 08:18:56,183] {standard_task_runner.py:52} INFO - Started process 113 to run task
[2023-04-27 08:18:56,200] {standard_task_runner.py:79} INFO - Running: ['***', 'tasks', 'run', 'attack_dag2', 'attack', 'scheduled__2023-04-23T00:00:00+00:00', '--job-id', '6290', '--raw', '--subdir', 'DAGS_FOLDER/attack.py', '--cfg-path', '/tmp/tmpi3mtp2ze', '--error-file', '/tmp/tmp_dkkj5fg']
[2023-04-27 08:18:56,204] {standard_task_runner.py:80} INFO - Job 6290: Subtask attack
[2023-04-27 08:18:56,403] {task_command.py:369} INFO - Running <TaskInstance: attack_dag2.attack scheduled__2023-04-23T00:00:00+00:00 [running]> on host e7e31d5a6603
[2023-04-27 08:18:56,765] {taskinstance.py:1571} INFO - Exporting the following env vars:
AIRFLOW_CTX_DAG_OWNER=***
AIRFLOW_CTX_DAG_ID=attack_dag2
AIRFLOW_CTX_TASK_ID=attack
AIRFLOW_CTX_EXECUTION_DATE=2023-04-23T00:00:00+00:00
AIRFLOW_CTX_TRY_NUMBER=1
AIRFLOW_CTX_DAG_RUN_ID=scheduled__2023-04-23T00:00:00+00:00
[2023-04-27 08:18:56,777] {transport.py:157} INFO - Attempting refresh to obtain initial access_token
[2023-04-27 08:18:56,795] {client.py:777} INFO - Refreshing access_token
[2023-04-27 08:18:57,282] {taskinstance.py:1889} ERROR - Task failed with exception
Traceback (most recent call last):
  File "/home/airflow/.local/lib/python3.7/site-packages/airflow/operators/python.py", line 171, in execute
    return_value = self.execute_callable()
  File "/home/airflow/.local/lib/python3.7/site-packages/airflow/operators/python.py", line 189, in execute_callable
    return self.python_callable(*self.op_args, **self.op_kwargs)
  File "/opt/airflow/dags/attack.py", line 36, in attack_A
    counter = load_from_bucket('counter.pickle')
  File "/opt/airflow/dags/helpers.py", line 121, in load_from_bucket
    raise err
  File "/opt/airflow/dags/helpers.py", line 116, in load_from_bucket
    blob.download_to_filename(file_name)
  File "/home/airflow/.local/lib/python3.7/site-packages/gcloud/storage/blob.py", line 369, in download_to_filename
    client=client)
  File "/home/airflow/.local/lib/python3.7/site-packages/gcloud/storage/blob.py", line 327, in download_to_file
    self.reload()
  File "/home/airflow/.local/lib/python3.7/site-packages/gcloud/storage/_helpers.py", line 77, in reload
    _target_object=self)
  File "/home/airflow/.local/lib/python3.7/site-packages/gcloud/connection.py", line 347, in api_request
    error_info=method + ' ' + url)
gcloud.exceptions.NotFound: 404 No such object: mabdata207125196/counter.pickle (GET https://www.googleapis.com/storage/v1/b/mabdata207125196/o/counter.pickle?projection=noAcl)
[2023-04-27 08:18:57,316] {taskinstance.py:1400} INFO - Marking task as FAILED. dag_id=attack_dag2, task_id=attack, execution_date=20230423T000000, start_date=20230427T081856, end_date=20230427T081857
[2023-04-27 08:18:57,346] {standard_task_runner.py:97} ERROR - Failed to execute job 6290 for task attack (404 No such object: mabdata207125196/counter.pickle (GET https://www.googleapis.com/storage/v1/b/mabdata207125196/o/counter.pickle?projection=noAcl); 113)
[2023-04-27 08:18:57,394] {local_task_job.py:156} INFO - Task exited with return code 1
[2023-04-27 08:18:57,482] {local_task_job.py:273} INFO - 0 downstream tasks scheduled from follow-on schedule check
