[2023-03-23 14:52:25,031] {taskinstance.py:1159} INFO - Dependencies all met for <TaskInstance: multi_defence_dag.to_defence1 scheduled__2023-03-22T00:00:00+00:00 [queued]>
[2023-03-23 14:52:25,120] {taskinstance.py:1159} INFO - Dependencies all met for <TaskInstance: multi_defence_dag.to_defence1 scheduled__2023-03-22T00:00:00+00:00 [queued]>
[2023-03-23 14:52:25,123] {taskinstance.py:1356} INFO - 
--------------------------------------------------------------------------------
[2023-03-23 14:52:25,126] {taskinstance.py:1357} INFO - Starting attempt 2 of 2
[2023-03-23 14:52:25,128] {taskinstance.py:1358} INFO - 
--------------------------------------------------------------------------------
[2023-03-23 14:52:25,230] {taskinstance.py:1377} INFO - Executing <Task(BranchPythonOperator): to_defence1> on 2023-03-22 00:00:00+00:00
[2023-03-23 14:52:25,248] {standard_task_runner.py:52} INFO - Started process 10876 to run task
[2023-03-23 14:52:25,269] {standard_task_runner.py:79} INFO - Running: ['***', 'tasks', 'run', 'multi_defence_dag', 'to_defence1', 'scheduled__2023-03-22T00:00:00+00:00', '--job-id', '2746', '--raw', '--subdir', 'DAGS_FOLDER/defence_dag.py', '--cfg-path', '/tmp/tmp_k0cq9_h', '--error-file', '/tmp/tmpadc_jub9']
[2023-03-23 14:52:25,275] {standard_task_runner.py:80} INFO - Job 2746: Subtask to_defence1
[2023-03-23 14:52:25,627] {task_command.py:369} INFO - Running <TaskInstance: multi_defence_dag.to_defence1 scheduled__2023-03-22T00:00:00+00:00 [running]> on host 6447f1dacd32
[2023-03-23 14:52:26,140] {taskinstance.py:1571} INFO - Exporting the following env vars:
AIRFLOW_CTX_DAG_OWNER=***
AIRFLOW_CTX_DAG_ID=multi_defence_dag
AIRFLOW_CTX_TASK_ID=to_defence1
AIRFLOW_CTX_EXECUTION_DATE=2023-03-22T00:00:00+00:00
AIRFLOW_CTX_TRY_NUMBER=2
AIRFLOW_CTX_DAG_RUN_ID=scheduled__2023-03-22T00:00:00+00:00
[2023-03-23 14:52:26,224] {python.py:173} INFO - Done. Returned value was: Defence1
[2023-03-23 14:52:26,323] {taskinstance.py:1889} ERROR - Task failed with exception
Traceback (most recent call last):
  File "/home/airflow/.local/lib/python3.7/site-packages/airflow/operators/python.py", line 221, in execute
    f"Branch callable must return valid task_ids. Invalid tasks found: {invalid_task_ids}"
airflow.exceptions.AirflowException: Branch callable must return valid task_ids. Invalid tasks found: {'Defence1'}
[2023-03-23 14:52:26,343] {taskinstance.py:1400} INFO - Marking task as FAILED. dag_id=multi_defence_dag, task_id=to_defence1, execution_date=20230322T000000, start_date=20230323T145225, end_date=20230323T145226
[2023-03-23 14:52:26,409] {standard_task_runner.py:97} ERROR - Failed to execute job 2746 for task to_defence1 (Branch callable must return valid task_ids. Invalid tasks found: {'Defence1'}; 10876)
[2023-03-23 14:52:26,452] {local_task_job.py:156} INFO - Task exited with return code 1
[2023-03-23 14:52:26,713] {local_task_job.py:273} INFO - 0 downstream tasks scheduled from follow-on schedule check
