[2023-04-30 07:59:34,543] {taskinstance.py:1159} INFO - Dependencies all met for <TaskInstance: defence_dag2.to_attack scheduled__2023-04-27T00:00:00+00:00 [queued]>
[2023-04-30 07:59:34,594] {taskinstance.py:1159} INFO - Dependencies all met for <TaskInstance: defence_dag2.to_attack scheduled__2023-04-27T00:00:00+00:00 [queued]>
[2023-04-30 07:59:34,595] {taskinstance.py:1356} INFO - 
--------------------------------------------------------------------------------
[2023-04-30 07:59:34,595] {taskinstance.py:1357} INFO - Starting attempt 1 of 1
[2023-04-30 07:59:34,596] {taskinstance.py:1358} INFO - 
--------------------------------------------------------------------------------
[2023-04-30 07:59:35,063] {taskinstance.py:1377} INFO - Executing <Task(BranchPythonOperator): to_attack> on 2023-04-27 00:00:00+00:00
[2023-04-30 07:59:35,088] {standard_task_runner.py:52} INFO - Started process 255 to run task
[2023-04-30 07:59:35,190] {standard_task_runner.py:79} INFO - Running: ['***', 'tasks', 'run', 'defence_dag2', 'to_attack', 'scheduled__2023-04-27T00:00:00+00:00', '--job-id', '7039', '--raw', '--subdir', 'DAGS_FOLDER/defese.py', '--cfg-path', '/tmp/tmpoplcllw0', '--error-file', '/tmp/tmpv9xdsmes']
[2023-04-30 07:59:35,192] {standard_task_runner.py:80} INFO - Job 7039: Subtask to_attack
[2023-04-30 07:59:35,945] {task_command.py:369} INFO - Running <TaskInstance: defence_dag2.to_attack scheduled__2023-04-27T00:00:00+00:00 [running]> on host e7e31d5a6603
[2023-04-30 07:59:36,332] {taskinstance.py:1571} INFO - Exporting the following env vars:
AIRFLOW_CTX_DAG_OWNER=***
AIRFLOW_CTX_DAG_ID=defence_dag2
AIRFLOW_CTX_TASK_ID=to_attack
AIRFLOW_CTX_EXECUTION_DATE=2023-04-27T00:00:00+00:00
AIRFLOW_CTX_TRY_NUMBER=1
AIRFLOW_CTX_DAG_RUN_ID=scheduled__2023-04-27T00:00:00+00:00
[2023-04-30 07:59:36,365] {transport.py:157} INFO - Attempting refresh to obtain initial access_token
[2023-04-30 07:59:36,385] {client.py:777} INFO - Refreshing access_token
[2023-04-30 07:59:37,027] {taskinstance.py:1889} ERROR - Task failed with exception
Traceback (most recent call last):
  File "/home/airflow/.local/lib/python3.7/site-packages/airflow/operators/python.py", line 207, in execute
    branch = super().execute(context)
  File "/home/airflow/.local/lib/python3.7/site-packages/airflow/operators/python.py", line 171, in execute
    return_value = self.execute_callable()
  File "/home/airflow/.local/lib/python3.7/site-packages/airflow/operators/python.py", line 189, in execute_callable
    return self.python_callable(*self.op_args, **self.op_kwargs)
  File "/opt/airflow/dags/defese.py", line 30, in to_attack
    cycles = load_from_bucket('counter.pickle')
  File "/opt/airflow/dags/helpers.py", line 122, in load_from_bucket
    raise err
  File "/opt/airflow/dags/helpers.py", line 117, in load_from_bucket
    blob.download_to_filename(file_name)
  File "/home/airflow/.local/lib/python3.7/site-packages/gcloud/storage/blob.py", line 369, in download_to_filename
    client=client)
  File "/home/airflow/.local/lib/python3.7/site-packages/gcloud/storage/blob.py", line 327, in download_to_file
    self.reload()
  File "/home/airflow/.local/lib/python3.7/site-packages/gcloud/storage/_helpers.py", line 77, in reload
    _target_object=self)
  File "/home/airflow/.local/lib/python3.7/site-packages/gcloud/connection.py", line 347, in api_request
    error_info=method + ' ' + url)
gcloud.exceptions.NotFound: 404 No such object: mabdata207125196/counter.pickle (GET https://www.googleapis.com/storage/v1/b/mabdata207125196/o/counter.pickle?projection=noAcl)
[2023-04-30 07:59:37,083] {taskinstance.py:1400} INFO - Marking task as FAILED. dag_id=defence_dag2, task_id=to_attack, execution_date=20230427T000000, start_date=20230430T075934, end_date=20230430T075937
[2023-04-30 07:59:37,141] {standard_task_runner.py:97} ERROR - Failed to execute job 7039 for task to_attack (404 No such object: mabdata207125196/counter.pickle (GET https://www.googleapis.com/storage/v1/b/mabdata207125196/o/counter.pickle?projection=noAcl); 255)
[2023-04-30 07:59:37,228] {local_task_job.py:156} INFO - Task exited with return code 1
[2023-04-30 07:59:37,648] {local_task_job.py:273} INFO - 0 downstream tasks scheduled from follow-on schedule check
