[2023-04-27 10:38:52,911] {taskinstance.py:1159} INFO - Dependencies all met for <TaskInstance: multi_attack_dag.attack_TargetedUniversalPerturbation manual__2023-04-27T10:30:40.186391+00:00 [queued]>
[2023-04-27 10:38:53,306] {taskinstance.py:1159} INFO - Dependencies all met for <TaskInstance: multi_attack_dag.attack_TargetedUniversalPerturbation manual__2023-04-27T10:30:40.186391+00:00 [queued]>
[2023-04-27 10:38:53,308] {taskinstance.py:1356} INFO - 
--------------------------------------------------------------------------------
[2023-04-27 10:38:53,322] {taskinstance.py:1357} INFO - Starting attempt 2 of 2
[2023-04-27 10:38:53,323] {taskinstance.py:1358} INFO - 
--------------------------------------------------------------------------------
[2023-04-27 10:38:53,700] {taskinstance.py:1377} INFO - Executing <Task(PythonOperator): attack_TargetedUniversalPerturbation> on 2023-04-27 10:30:40.186391+00:00
[2023-04-27 10:38:53,949] {standard_task_runner.py:52} INFO - Started process 5678 to run task
[2023-04-27 10:38:53,998] {standard_task_runner.py:79} INFO - Running: ['***', 'tasks', 'run', 'multi_attack_dag', 'attack_TargetedUniversalPerturbation', 'manual__2023-04-27T10:30:40.186391+00:00', '--job-id', '6640', '--raw', '--subdir', 'DAGS_FOLDER/attack_dag.py', '--cfg-path', '/tmp/tmpsz2ove1v', '--error-file', '/tmp/tmps_exe0lf']
[2023-04-27 10:38:54,149] {standard_task_runner.py:80} INFO - Job 6640: Subtask attack_TargetedUniversalPerturbation
[2023-04-27 10:38:55,100] {task_command.py:369} INFO - Running <TaskInstance: multi_attack_dag.attack_TargetedUniversalPerturbation manual__2023-04-27T10:30:40.186391+00:00 [running]> on host e7e31d5a6603
[2023-04-27 10:38:56,560] {taskinstance.py:1571} INFO - Exporting the following env vars:
AIRFLOW_CTX_DAG_OWNER=***
AIRFLOW_CTX_DAG_ID=multi_attack_dag
AIRFLOW_CTX_TASK_ID=attack_TargetedUniversalPerturbation
AIRFLOW_CTX_EXECUTION_DATE=2023-04-27T10:30:40.186391+00:00
AIRFLOW_CTX_TRY_NUMBER=2
AIRFLOW_CTX_DAG_RUN_ID=manual__2023-04-27T10:30:40.186391+00:00
[2023-04-27 10:38:56,575] {transport.py:157} INFO - Attempting refresh to obtain initial access_token
[2023-04-27 10:38:56,625] {client.py:777} INFO - Refreshing access_token
[2023-04-27 10:38:57,692] {transport.py:157} INFO - Attempting refresh to obtain initial access_token
[2023-04-27 10:38:57,703] {client.py:777} INFO - Refreshing access_token
[2023-04-27 10:39:23,300] {pytorch.py:1198} INFO - Inferred 5 hidden layers on PyTorch classifier.
[2023-04-27 10:43:04,650] {attack_dag.py:643} INFO - Optimizing...
[2023-04-27 10:43:04,652] {logging_mixin.py:115} INFO - I am right here on <class 'art.attacks.evasion.targeted_universal_perturbation.TargetedUniversalPerturbation'>
[2023-04-27 10:43:04,652] {taskinstance.py:1889} ERROR - Task failed with exception
Traceback (most recent call last):
  File "/opt/airflow/dags/attack_dag.py", line 645, in attack
    optimized_attack = optimize_evasion_attack(attack_obj,estimator,x_test,y_test)
  File "/opt/airflow/dags/attack_dag.py", line 617, in optimize_evasion_attack
    search_space = [v for k, v in attack_parameter_range[attack.__name__].items()]
KeyError: 'TargetedUniversalPerturbation'

During handling of the above exception, another exception occurred:

Traceback (most recent call last):
  File "/home/airflow/.local/lib/python3.7/site-packages/airflow/operators/python.py", line 171, in execute
    return_value = self.execute_callable()
  File "/home/airflow/.local/lib/python3.7/site-packages/airflow/operators/python.py", line 189, in execute_callable
    return self.python_callable(*self.op_args, **self.op_kwargs)
  File "/opt/airflow/dags/attack_dag.py", line 415, in attack_TargetedUniversalPerturbation
    model_acc, adversarial_examples  = attack(TargetedUniversalPerturbation)
  File "/opt/airflow/dags/attack_dag.py", line 648, in attack
    optimized_attack = attack_obj(estimator=estimator, eps=0.2)
TypeError: __init__() got an unexpected keyword argument 'estimator'
[2023-04-27 10:43:04,720] {taskinstance.py:1400} INFO - Marking task as FAILED. dag_id=multi_attack_dag, task_id=attack_TargetedUniversalPerturbation, execution_date=20230427T103040, start_date=20230427T103852, end_date=20230427T104304
[2023-04-27 10:43:04,791] {standard_task_runner.py:97} ERROR - Failed to execute job 6640 for task attack_TargetedUniversalPerturbation (__init__() got an unexpected keyword argument 'estimator'; 5678)
[2023-04-27 10:43:04,885] {local_task_job.py:156} INFO - Task exited with return code 1
[2023-04-27 10:43:05,095] {local_task_job.py:273} INFO - 0 downstream tasks scheduled from follow-on schedule check
