[2023-04-27 12:27:34,328] {taskinstance.py:1159} INFO - Dependencies all met for <TaskInstance: multi_attack_dag.attack_AutoAttack manual__2023-04-27T12:25:48.345057+00:00 [queued]>
[2023-04-27 12:27:34,384] {taskinstance.py:1159} INFO - Dependencies all met for <TaskInstance: multi_attack_dag.attack_AutoAttack manual__2023-04-27T12:25:48.345057+00:00 [queued]>
[2023-04-27 12:27:34,387] {taskinstance.py:1356} INFO - 
--------------------------------------------------------------------------------
[2023-04-27 12:27:34,391] {taskinstance.py:1357} INFO - Starting attempt 1 of 2
[2023-04-27 12:27:34,404] {taskinstance.py:1358} INFO - 
--------------------------------------------------------------------------------
[2023-04-27 12:27:34,450] {taskinstance.py:1377} INFO - Executing <Task(PythonOperator): attack_AutoAttack> on 2023-04-27 12:25:48.345057+00:00
[2023-04-27 12:27:34,482] {standard_task_runner.py:52} INFO - Started process 4057 to run task
[2023-04-27 12:27:34,562] {standard_task_runner.py:79} INFO - Running: ['***', 'tasks', 'run', 'multi_attack_dag', 'attack_AutoAttack', 'manual__2023-04-27T12:25:48.345057+00:00', '--job-id', '6840', '--raw', '--subdir', 'DAGS_FOLDER/attack_dag.py', '--cfg-path', '/tmp/tmplu7l4w5m', '--error-file', '/tmp/tmp9hpr6lsk']
[2023-04-27 12:27:34,607] {standard_task_runner.py:80} INFO - Job 6840: Subtask attack_AutoAttack
[2023-04-27 12:27:35,241] {task_command.py:369} INFO - Running <TaskInstance: multi_attack_dag.attack_AutoAttack manual__2023-04-27T12:25:48.345057+00:00 [running]> on host e7e31d5a6603
[2023-04-27 12:27:36,084] {taskinstance.py:1571} INFO - Exporting the following env vars:
AIRFLOW_CTX_DAG_OWNER=***
AIRFLOW_CTX_DAG_ID=multi_attack_dag
AIRFLOW_CTX_TASK_ID=attack_AutoAttack
AIRFLOW_CTX_EXECUTION_DATE=2023-04-27T12:25:48.345057+00:00
AIRFLOW_CTX_TRY_NUMBER=1
AIRFLOW_CTX_DAG_RUN_ID=manual__2023-04-27T12:25:48.345057+00:00
[2023-04-27 12:27:36,091] {transport.py:157} INFO - Attempting refresh to obtain initial access_token
[2023-04-27 12:27:36,105] {client.py:777} INFO - Refreshing access_token
[2023-04-27 12:27:37,013] {transport.py:157} INFO - Attempting refresh to obtain initial access_token
[2023-04-27 12:27:37,058] {client.py:777} INFO - Refreshing access_token
[2023-04-27 12:28:10,814] {pytorch.py:1198} INFO - Inferred 5 hidden layers on PyTorch classifier.
[2023-04-27 12:34:49,094] {local_task_job.py:221} WARNING - State of this instance has been externally set to removed. Terminating instance.
[2023-04-27 12:34:49,127] {process_utils.py:129} INFO - Sending Signals.SIGTERM to group 4057. PIDs of all processes in the group: [4057]
[2023-04-27 12:34:49,135] {process_utils.py:80} INFO - Sending the signal Signals.SIGTERM to group 4057
[2023-04-27 12:34:49,487] {taskinstance.py:1541} ERROR - Received SIGTERM. Terminating subprocesses.
[2023-04-27 12:34:50,507] {taskinstance.py:1889} ERROR - Task failed with exception
Traceback (most recent call last):
  File "/home/airflow/.local/lib/python3.7/site-packages/airflow/operators/python.py", line 171, in execute
    return_value = self.execute_callable()
  File "/home/airflow/.local/lib/python3.7/site-packages/airflow/operators/python.py", line 189, in execute_callable
    return self.python_callable(*self.op_args, **self.op_kwargs)
  File "/opt/airflow/dags/attack.py", line 121, in attack_AutoAttack
    model_acc, adversarial_examples  = attack(AutoAttack)
  File "/opt/airflow/dags/attack.py", line 31, in attack
    estimator,x_test,y_test = get_estimator()
  File "/opt/airflow/dags/estimator_helpers.py", line 51, in get_estimator
    clf, data,true_labels = s.make_trained_model(model)
  File "/opt/airflow/dags/Model_Factory.py", line 106, in make_trained_model
    clf, data, true_labels = self.__make_trained_CC_model(model)
  File "/opt/airflow/dags/Model_Factory.py", line 71, in __make_trained_CC_model
    classifier_CC.fit(X_train, y_train, batch_size=32, nb_epochs=20)
  File "/home/airflow/.local/lib/python3.7/site-packages/art/estimators/classification/classifier.py", line 73, in replacement_function
    return fdict[func_name](self, *args, **kwargs)
  File "/home/airflow/.local/lib/python3.7/site-packages/art/estimators/classification/pytorch.py", line 456, in fit
    loss.backward()
  File "/home/airflow/.local/lib/python3.7/site-packages/torch/_tensor.py", line 489, in backward
    self, gradient, retain_graph, create_graph, inputs=inputs
  File "/home/airflow/.local/lib/python3.7/site-packages/torch/autograd/__init__.py", line 199, in backward
    allow_unreachable=True, accumulate_grad=True)  # Calls into the C++ engine to run the backward pass
  File "/home/airflow/.local/lib/python3.7/site-packages/airflow/models/taskinstance.py", line 1543, in signal_handler
    raise AirflowException("Task received SIGTERM signal")
airflow.exceptions.AirflowException: Task received SIGTERM signal
[2023-04-27 12:34:51,077] {taskinstance.py:1400} INFO - Marking task as FAILED. dag_id=multi_attack_dag, task_id=attack_AutoAttack, execution_date=20230427T122548, start_date=20230427T122734, end_date=20230427T123450
[2023-04-27 12:34:51,525] {standard_task_runner.py:97} ERROR - Failed to execute job 6840 for task attack_AutoAttack (Task received SIGTERM signal; 4057)
[2023-04-27 12:34:52,081] {process_utils.py:75} INFO - Process psutil.Process(pid=4057, status='terminated', exitcode=1, started='12:27:34') (4057) terminated with exit code 1
