[2023-03-28 09:40:21,668] {taskinstance.py:1159} INFO - Dependencies all met for <TaskInstance: defence_dag2.to_attack manual__2023-03-27T12:40:58.379305+00:00 [queued]>
[2023-03-28 09:40:21,694] {taskinstance.py:1159} INFO - Dependencies all met for <TaskInstance: defence_dag2.to_attack manual__2023-03-27T12:40:58.379305+00:00 [queued]>
[2023-03-28 09:40:21,695] {taskinstance.py:1356} INFO - 
--------------------------------------------------------------------------------
[2023-03-28 09:40:21,696] {taskinstance.py:1357} INFO - Starting attempt 1 of 1
[2023-03-28 09:40:21,698] {taskinstance.py:1358} INFO - 
--------------------------------------------------------------------------------
[2023-03-28 09:40:21,738] {taskinstance.py:1377} INFO - Executing <Task(BranchPythonOperator): to_attack> on 2023-03-27 12:40:58.379305+00:00
[2023-03-28 09:40:21,747] {standard_task_runner.py:52} INFO - Started process 195 to run task
[2023-03-28 09:40:21,749] {standard_task_runner.py:79} INFO - Running: ['***', 'tasks', 'run', 'defence_dag2', 'to_attack', 'manual__2023-03-27T12:40:58.379305+00:00', '--job-id', '3914', '--raw', '--subdir', 'DAGS_FOLDER/defese.py', '--cfg-path', '/tmp/tmpsx70574c', '--error-file', '/tmp/tmpmfclpc0b']
[2023-03-28 09:40:21,752] {standard_task_runner.py:80} INFO - Job 3914: Subtask to_attack
[2023-03-28 09:40:21,897] {task_command.py:369} INFO - Running <TaskInstance: defence_dag2.to_attack manual__2023-03-27T12:40:58.379305+00:00 [running]> on host 70f8824ef075
[2023-03-28 09:40:22,168] {taskinstance.py:1571} INFO - Exporting the following env vars:
AIRFLOW_CTX_DAG_OWNER=***
AIRFLOW_CTX_DAG_ID=defence_dag2
AIRFLOW_CTX_TASK_ID=to_attack
AIRFLOW_CTX_EXECUTION_DATE=2023-03-27T12:40:58.379305+00:00
AIRFLOW_CTX_TRY_NUMBER=1
AIRFLOW_CTX_DAG_RUN_ID=manual__2023-03-27T12:40:58.379305+00:00
[2023-03-28 09:40:22,175] {transport.py:157} INFO - Attempting refresh to obtain initial access_token
[2023-03-28 09:40:22,183] {client.py:777} INFO - Refreshing access_token
[2023-03-28 09:40:23,423] {taskinstance.py:1889} ERROR - Task failed with exception
Traceback (most recent call last):
  File "/home/airflow/.local/lib/python3.7/site-packages/airflow/operators/python.py", line 207, in execute
    branch = super().execute(context)
  File "/home/airflow/.local/lib/python3.7/site-packages/airflow/operators/python.py", line 171, in execute
    return_value = self.execute_callable()
  File "/home/airflow/.local/lib/python3.7/site-packages/airflow/operators/python.py", line 189, in execute_callable
    return self.python_callable(*self.op_args, **self.op_kwargs)
  File "/opt/airflow/dags/defese.py", line 30, in to_attack
    cycles = load_from_bucket('counter.pickle').cycles
AttributeError: 'NoneType' object has no attribute 'cycles'
[2023-03-28 09:40:23,436] {taskinstance.py:1400} INFO - Marking task as FAILED. dag_id=defence_dag2, task_id=to_attack, execution_date=20230327T124058, start_date=20230328T094021, end_date=20230328T094023
[2023-03-28 09:40:23,453] {standard_task_runner.py:97} ERROR - Failed to execute job 3914 for task to_attack ('NoneType' object has no attribute 'cycles'; 195)
[2023-03-28 09:40:23,496] {local_task_job.py:156} INFO - Task exited with return code 1
[2023-03-28 09:40:23,554] {local_task_job.py:273} INFO - 0 downstream tasks scheduled from follow-on schedule check
